<?xml version="1.0" ?>
<robot name="partnet_f7e0a103c97469d5a168e247bb97e471">
	<link name="base"/>
	<link name="link_0">
		<visual name="door_frame-21">
			<origin xyz="-0.3222042194546104 -0.8713290095329285 -0.3357881237454305"/>
			<geometry>
				<mesh filename="textured_objs/original-15.obj"/>
			</geometry>
		</visual>
		<collision>
			<origin xyz="-0.3222042194546104 -0.8713290095329285 -0.3357881237454305"/>
			<geometry>
				<mesh filename="textured_objs/original-15.obj"/>
			</geometry>
		</collision>
	</link>
	<joint name="joint_0" type="revolute">
		<origin xyz="0.3222042194546104 0.8713290095329285 0.3357881237454305"/>
		<axis xyz="0 1 0"/>
		<child link="link_0"/>
		<parent link="link_2"/>
		<limit lower="0.0" upper="1.5707963267948966"/>
	</joint>
	<link name="link_1">
		<visual name="door_frame-19">
			<origin xyz="-0.3222042194546104 -0.8713290095329285 -0.3357881237454305"/>
			<geometry>
				<mesh filename="textured_objs/original-3.obj"/>
			</geometry>
		</visual>
		<collision>
			<origin xyz="-0.3222042194546104 -0.8713290095329285 -0.3357881237454305"/>
			<geometry>
				<mesh filename="textured_objs/original-3.obj"/>
			</geometry>
		</collision>
	</link>
	<joint name="joint_1" type="revolute">
		<origin xyz="0.3222042194546104 0.8713290095329285 0.3357881237454305"/>
		<axis xyz="0 1 0"/>
		<child link="link_1"/>
		<parent link="link_2"/>
		<limit lower="0.0" upper="1.5707963267948966"/>
	</joint>
	<link name="link_2">
		<visual name="frame-15">
			<origin xyz="0 0 0"/>
			<geometry>
				<mesh filename="textured_objs/original-4.obj"/>
			</geometry>
		</visual>
		<visual name="frame-15">
			<origin xyz="0 0 0"/>
			<geometry>
				<mesh filename="textured_objs/original-2.obj"/>
			</geometry>
		</visual>
		<visual name="frame-15">
			<origin xyz="0 0 0"/>
			<geometry>
				<mesh filename="textured_objs/original-9.obj"/>
			</geometry>
		</visual>
		<visual name="frame-15">
			<origin xyz="0 0 0"/>
			<geometry>
				<mesh filename="textured_objs/original-1.obj"/>
			</geometry>
		</visual>
		<visual name="frame-15">
			<origin xyz="0 0 0"/>
			<geometry>
				<mesh filename="textured_objs/original-10.obj"/>
			</geometry>
		</visual>
		<visual name="shelf-23">
			<origin xyz="0 0 0"/>
			<geometry>
				<mesh filename="textured_objs/original-16.obj"/>
			</geometry>
		</visual>
		<collision>
			<origin xyz="0 0 0"/>
			<geometry>
				<mesh filename="textured_objs/original-4.obj"/>
			</geometry>
		</collision>
		<collision>
			<origin xyz="0 0 0"/>
			<geometry>
				<mesh filename="textured_objs/original-2.obj"/>
			</geometry>
		</collision>
		<collision>
			<origin xyz="0 0 0"/>
			<geometry>
				<mesh filename="textured_objs/original-9.obj"/>
			</geometry>
		</collision>
		<collision>
			<origin xyz="0 0 0"/>
			<geometry>
				<mesh filename="textured_objs/original-1.obj"/>
			</geometry>
		</collision>
		<collision>
			<origin xyz="0 0 0"/>
			<geometry>
				<mesh filename="textured_objs/original-10.obj"/>
			</geometry>
		</collision>
		<collision>
			<origin xyz="0 0 0"/>
			<geometry>
				<mesh filename="textured_objs/original-16.obj"/>
			</geometry>
		</collision>
	</link>
	<joint name="joint_2" type="fixed">
		<origin rpy="1.570796326794897 0 -1.570796326794897" xyz="0 0 0"/>
		<child link="link_2"/>
		<parent link="base"/>
	</joint>
		<link name="link_3">
			<visual name="handle-1">
				<origin xyz="-0.3222042194546104 -0.8713290095329285 -0.3357881237454305"/>
				<geometry>
					<mesh filename="textured_objs/original-12.obj"/>
				</geometry>
		</visual>
		<visual name="handle-1">
			<origin xyz="-0.3222042194546104 -0.8713290095329285 -0.3357881237454305"/>
			<geometry>
				<mesh filename="textured_objs/modified-0-original-14.obj"/>
			</geometry>
		</visual>
		<visual name="handle-1">
			<origin xyz="-0.3222042194546104 -0.8713290095329285 -0.3357881237454305"/>
			<geometry>
				<mesh filename="textured_objs/modified-0-original-13.obj"/>
			</geometry>
		</visual>
			<collision>
				<origin xyz="-0.3222042194546104 -0.8713290095329285 -0.3357881237454305"/>
				<geometry>
					<mesh filename="textured_objs/original-12.obj" scale="1.5 2.0 1.0"/>
				</geometry>
		</collision>
		<collision>
			<origin xyz="-0.3222042194546104 -0.8713290095329285 -0.3357881237454305"/>
			<geometry>
				<mesh filename="textured_objs/modified-0-original-14.obj" scale="1.5 2.0 1.0"/>
			</geometry>
		</collision>
		<collision>
			<origin xyz="-0.3222042194546104 -0.8713290095329285 -0.3357881237454305"/>
			<geometry>
				<mesh filename="textured_objs/modified-0-original-13.obj" scale="1.5 2.0 1.0"/>
			</geometry>
		</collision>
	</link>
		<joint name="joint_3" type="fixed">
			<origin rpy="0 0 0" xyz="0 0 0"/>
			<child link="link_3"/>
			<parent link="link_0"/>
		</joint>
		<link name="link_4">
			<visual name="handle-1">
				<origin xyz="-0.3222042194546104 -0.8713290095329285 -0.3357881237454305"/>
				<geometry>
					<mesh filename="textured_objs/original-6.obj"/>
				</geometry>
		</visual>
		<visual name="handle-1">
			<origin xyz="-0.3222042194546104 -0.8713290095329285 -0.3357881237454305"/>
			<geometry>
				<mesh filename="textured_objs/modified-0-original-8.obj"/>
			</geometry>
		</visual>
		<visual name="handle-1">
			<origin xyz="-0.3222042194546104 -0.8713290095329285 -0.3357881237454305"/>
			<geometry>
				<mesh filename="textured_objs/modified-0-original-7.obj"/>
			</geometry>
		</visual>
			<collision>
				<origin xyz="-0.3222042194546104 -0.8713290095329285 -0.3357881237454305"/>
				<geometry>
					<mesh filename="textured_objs/original-6.obj" scale="1.5 2.0 1.0"/>
				</geometry>
		</collision>
		<collision>
			<origin xyz="-0.3222042194546104 -0.8713290095329285 -0.3357881237454305"/>
			<geometry>
				<mesh filename="textured_objs/modified-0-original-8.obj" scale="1.5 2.0 1.0"/>
			</geometry>
		</collision>
		<collision>
			<origin xyz="-0.3222042194546104 -0.8713290095329285 -0.3357881237454305"/>
			<geometry>
				<mesh filename="textured_objs/modified-0-original-7.obj" scale="1.5 2.0 1.0"/>
			</geometry>
		</collision>
	</link>
		<joint name="joint_4" type="fixed">
			<origin rpy="0 0 0" xyz="0 0 0"/>
			<child link="link_4"/>
			<parent link="link_1"/>
		</joint>
</robot>
